<?xml version="1.0" encoding="utf-8"?>
<!-- This URDF was automatically created by SolidWorks to URDF Exporter! Originally created by Stephen Brawner (brawner@gmail.com) 
     Commit Version: 1.6.0-4-g7f85cfe  Build Version: 1.6.7995.38578
     For more information, please see http://wiki.ros.org/sw_urdf_exporter -->
<robot
  name="spider1">
  <link
    name="base_link">
    <inertial>
      <origin
        xyz="0.0023278 0.00485 0.0023771"
        rpy="0 0 0" />
      <mass
        value="0.065616" />
      <inertia
        ixx="4.2481E-05"
        ixy="-5.904E-14"
        ixz="-3.5801E-22"
        iyy="2.1517E-05"
        iyz="1.9781E-09"
        izz="5.9904E-05" />
    </inertial>
    <visual>
      <origin
        xyz="0 0 0"
        rpy="0 0 0" />
      <geometry>
        <mesh
          filename="package://spider/meshes/base_link.STL" />
      </geometry>
      <material
        name="">
        <color
          rgba="0.79216 0.81961 0.93333 1" />
      </material>
    </visual>
    <collision>
      <origin
        xyz="0 0 0"
        rpy="0 0 0" />
      <geometry>
        <mesh
          filename="package://spider/meshes/base_link.STL" />
      </geometry>
    </collision>
  </link>
  <link
    name="f1">
    <inertial>
      <origin
        xyz="-0.018401 0.01659 0.003534"
        rpy="0 0 0" />
      <mass
        value="0.011831" />
      <inertia
        ixx="1.5646E-06"
        ixy="9.7054E-09"
        ixz="-3.045E-08"
        iyy="1.457E-06"
        iyz="-1.7785E-08"
        izz="1.0395E-06" />
    </inertial>
    <visual>
      <origin
        xyz="0 0 0"
        rpy="0 0 0" />
      <geometry>
        <mesh
          filename="package://spider/meshes/f1.STL" />
      </geometry>
      <material
        name="">
        <color
          rgba="0.79216 0.81961 0.93333 1" />
      </material>
    </visual>
    <collision>
      <origin
        xyz="0 0 0"
        rpy="0 0 0" />
      <geometry>
        <mesh
          filename="package://spider/meshes/f1.STL" />
      </geometry>
    </collision>
  </link>
  <joint
    name="f1_joint"
    type="revolute">
    <origin
      xyz="-0.033172 0.040513 0.0037238"
      rpy="0 0 0" />
    <parent
      link="base_link" />
    <child
      link="f1" />
    <axis
      xyz="0 0 -1" />
    <limit
      lower="-3.14"
      upper="3.14"
      effort="1"
      velocity="1" />
    <dynamics
      damping="1"
      friction="1" />
  </joint>
  <link
    name="f11">
    <inertial>
      <origin
        xyz="-0.00312800502450068 0.029304654512747 0.0109553755380737"
        rpy="0 0 0" />
      <mass
        value="0.00732061922605988" />
      <inertia
        ixx="1.89519682514823E-06"
        ixy="-4.81247392753302E-08"
        ixz="4.17488981091791E-07"
        iyy="1.90454664060193E-06"
        iyz="-4.74204996799255E-07"
        izz="3.0470393635977E-06" />
    </inertial>
    <visual>
      <origin
        xyz="0 0 0"
        rpy="0 0 0" />
      <geometry>
        <mesh
          filename="package://spider/meshes/f11.STL" />
      </geometry>
      <material
        name="">
        <color
          rgba="0.792156862745098 0.819607843137255 0.933333333333333 1" />
      </material>
    </visual>
    <collision>
      <origin
        xyz="0 0 0"
        rpy="0 0 0" />
      <geometry>
        <mesh
          filename="package://spider/meshes/f11.STL" />
      </geometry>
    </collision>
  </link>
  <joint
    name="f11_joint"
    type="revolute">
    <origin
      xyz="-0.03439 0.0063335 0.0084"
      rpy="0 0 0" />
    <parent
      link="f1" />
    <child
      link="f11" />
    <axis
      xyz="-0.74991 -0.66153 0" />
    <limit
      lower="-3.14"
      upper="3.14"
      effort="1"
      velocity="1" />
    <dynamics
      damping="1"
      friction="1" />
  </joint>
  <link
    name="f111">
    <inertial>
      <origin
        xyz="0.00700565537465488 0.0174495821523415 -0.0100072504512934"
        rpy="0 0 0" />
      <mass
        value="0.0131238915006959" />
      <inertia
        ixx="3.81248468902086E-06"
        ixy="4.89789117554809E-07"
        ixz="-1.09704738692261E-06"
        iyy="3.66531231134112E-06"
        iyz="1.33727196442167E-06"
        izz="1.95892271569825E-06" />
    </inertial>
    <visual>
      <origin
        xyz="0 0 0"
        rpy="0 0 0" />
      <geometry>
        <mesh
          filename="package://spider/meshes/f111.STL" />
      </geometry>
      <material
        name="">
        <color
          rgba="0.792156862745098 0.819607843137255 0.933333333333333 1" />
      </material>
    </visual>
    <collision>
      <origin
        xyz="0 0 0"
        rpy="0 0 0" />
      <geometry>
        <mesh
          filename="package://spider/meshes/f111.STL" />
      </geometry>
    </collision>
  </link>
  <joint
    name="f111_joint"
    type="revolute">
    <origin
      xyz="-0.03266 0.03793 0.022803"
      rpy="0 0 0" />
    <parent
      link="f11" />
    <child
      link="f111" />
    <axis
      xyz="0.74991 0.66153 0" />
    <limit
      lower="-3.14"
      upper="3.14"
      effort="1"
      velocity="1" />
    <dynamics
      damping="1"
      friction="1" />
  </joint>
  <link
    name="f2">
    <inertial>
      <origin
        xyz="0.0151948529255643 0.0194570105580934 -0.0150449894403129"
        rpy="0 0 0" />
      <mass
        value="0.0118214556601813" />
      <inertia
        ixx="1.56348678645003E-06"
        ixy="-1.19050069760458E-08"
        ixz="3.0571500046444E-08"
        iyy="1.45629734097349E-06"
        iyz="-1.85639441950684E-08"
        izz="1.03828177179975E-06" />
    </inertial>
    <visual>
      <origin
        xyz="0 0 0"
        rpy="0 0 0" />
      <geometry>
        <mesh
          filename="package://spider/meshes/f2.STL" />
      </geometry>
      <material
        name="">
        <color
          rgba="0.792156862745098 0.819607843137255 0.933333333333333 1" />
      </material>
    </visual>
    <collision>
      <origin
        xyz="0 0 0"
        rpy="0 0 0" />
      <geometry>
        <mesh
          filename="package://spider/meshes/f2.STL" />
      </geometry>
    </collision>
  </link>
  <joint
    name="f2_joint"
    type="revolute">
    <origin
      xyz="0.037828 0.040513 0.022299"
      rpy="0 0 0" />
    <parent
      link="base_link" />
    <child
      link="f2" />
    <axis
      xyz="0 0 1" />
    <limit
      lower="-3.14"
      upper="3.14"
      effort="1"
      velocity="1" />
    <dynamics
      damping="1"
      friction="1" />
  </joint>
  <link
    name="f22">
    <inertial>
      <origin
        xyz="0.00310211145807297 0.0287358528716765 0.0123772011765127"
        rpy="0 0 0" />
      <mass
        value="0.00732061922605988" />
      <inertia
        ixx="1.93264517468614E-06"
        ixy="8.78459053149969E-08"
        ixz="-4.65779598189396E-07"
        iyy="1.94666462959028E-06"
        iyz="-5.1314367047501E-07"
        izz="2.96747302507144E-06" />
    </inertial>
    <visual>
      <origin
        xyz="0 0 0"
        rpy="0 0 0" />
      <geometry>
        <mesh
          filename="package://spider/meshes/f22.STL" />
      </geometry>
      <material
        name="">
        <color
          rgba="0.792156862745098 0.819607843137255 0.933333333333333 1" />
      </material>
    </visual>
    <collision>
      <origin
        xyz="0 0 0"
        rpy="0 0 0" />
      <geometry>
        <mesh
          filename="package://spider/meshes/f22.STL" />
      </geometry>
    </collision>
  </link>
  <joint
    name="f22_joint"
    type="revolute">
    <origin
      xyz="0.029378 0.010453 -0.010175"
      rpy="0 0 0" />
    <parent
      link="f2" />
    <child
      link="f22" />
    <axis
      xyz="0.73977 -0.67286 0" />
    <limit
      lower="-3.14"
      upper="3.14"
      effort="1"
      velocity="1" />
    <dynamics
      damping="1"
      friction="1" />
  </joint>
  <link
    name="f222">
    <inertial>
      <origin
        xyz="-0.0070653 0.018088 -0.0098563"
        rpy="0 0 0" />
      <mass
        value="0.013124" />
      <inertia
        ixx="3.7708E-06"
        ixy="-5.2231E-07"
        ixz="1.132E-06"
        iyy="3.6455E-06"
        iyz="1.3363E-06"
        izz="2.0204E-06" />
    </inertial>
    <visual>
      <origin
        xyz="0 0 0"
        rpy="0 0 0" />
      <geometry>
        <mesh
          filename="package://spider/meshes/f222.STL" />
      </geometry>
      <material
        name="">
        <color
          rgba="0.0078431 0.23922 0.82353 1" />
      </material>
    </visual>
    <collision>
      <origin
        xyz="0 0 0"
        rpy="0 0 0" />
      <geometry>
        <mesh
          filename="package://spider/meshes/f222.STL" />
      </geometry>
    </collision>
  </link>
  <joint
    name="f222_joint"
    type="revolute">
    <origin
      xyz="0.032696 0.035948 0.025763"
      rpy="0 0 0" />
    <parent
      link="f22" />
    <child
      link="f222" />
    <axis
      xyz="0.73977 -0.67286 0" />
    <limit
      lower="-3.14"
      upper="3.14"
      effort="1"
      velocity="1" />
    <dynamics
      damping="1"
      friction="1" />
  </joint>
  <link
    name="b1">
    <inertial>
      <origin
        xyz="-0.0160637632179106 -0.018746048290921 0.00495501051265646"
        rpy="0 0 0" />
      <mass
        value="0.0118214555384042" />
      <inertia
        ixx="1.56218378004245E-06"
        ixy="-1.67241701079202E-08"
        ixz="-2.9695871646277E-08"
        iyy="1.45760030760269E-06"
        iyz="1.99346925009862E-08"
        izz="1.03828176417558E-06" />
    </inertial>
    <visual>
      <origin
        xyz="0 0 0"
        rpy="0 0 0" />
      <geometry>
        <mesh
          filename="package://spider/meshes/b1.STL" />
      </geometry>
      <material
        name="">
        <color
          rgba="0.792156862745098 0.819607843137255 0.933333333333333 1" />
      </material>
    </visual>
    <collision>
      <origin
        xyz="0 0 0"
        rpy="0 0 0" />
      <geometry>
        <mesh
          filename="package://spider/meshes/b1.STL" />
      </geometry>
    </collision>
  </link>
  <joint
    name="b1_joint"
    type="revolute">
    <origin
      xyz="-0.033172 -0.030487 0.0022988"
      rpy="0 0 0" />
    <parent
      link="base_link" />
    <child
      link="b1" />
    <axis
      xyz="0 0 1" />
    <limit
      lower="-3.14"
      upper="3.14"
      effort="1"
      velocity="1" />
    <dynamics
      damping="1"
      friction="1" />
  </joint>
  <link
    name="b11">
    <inertial>
      <origin
        xyz="-0.028205 -0.0055557 0.011389"
        rpy="0 0 0" />
      <mass
        value="0.0073206" />
      <inertia
        ixx="1.9126E-06"
        ixy="5.9968E-08"
        ixz="4.5922E-07"
        iyy="1.9104E-06"
        iyz="4.6184E-07"
        izz="3.0238E-06" />
    </inertial>
    <visual>
      <origin
        xyz="0 0 0"
        rpy="0 0 0" />
      <geometry>
        <mesh
          filename="package://spider/meshes/b11.STL" />
      </geometry>
      <material
        name="">
        <color
          rgba="0.79216 0.81961 0.93333 1" />
      </material>
    </visual>
    <collision>
      <origin
        xyz="0 0 0"
        rpy="0 0 0" />
      <geometry>
        <mesh
          filename="package://spider/meshes/b11.STL" />
      </geometry>
    </collision>
  </link>
  <joint
    name="b11_joint"
    type="revolute">
    <origin
      xyz="-0.0063746 -0.032468 0.009825"
      rpy="0 0 0" />
    <parent
      link="b1" />
    <child
      link="b11" />
    <axis
      xyz="-0.70841 0.7058 0" />
    <limit
      lower="-3.14"
      upper="3.14"
      effort="1"
      velocity="1" />
    <dynamics
      damping="1"
      friction="1" />
  </joint>
  <link
    name="b111">
    <inertial>
      <origin
        xyz="-0.0171462112923383 0.0050386067181125 -0.00993818888067149"
        rpy="0 0 0" />
      <mass
        value="0.0131238943670332" />
      <inertia
        ixx="3.73910124940875E-06"
        ixy="-5.09192749678692E-07"
        ixz="-1.18341224274172E-06"
        iyy="3.71049698439754E-06"
        iyz="-1.27544845268077E-06"
        izz="1.98712199995714E-06" />
    </inertial>
    <visual>
      <origin
        xyz="0 0 0"
        rpy="0 0 0" />
      <geometry>
        <mesh
          filename="package://spider/meshes/b111.STL" />
      </geometry>
      <material
        name="">
        <color
          rgba="0.792156862745098 0.819607843137255 0.933333333333333 1" />
      </material>
    </visual>
    <collision>
      <origin
        xyz="0 0 0"
        rpy="0 0 0" />
      <geometry>
        <mesh
          filename="package://spider/meshes/b111.STL" />
      </geometry>
    </collision>
  </link>
  <joint
    name="b111_joint"
    type="revolute">
    <origin
      xyz="-0.035028 -0.035157 0.023707"
      rpy="0 0 0" />
    <parent
      link="b11" />
    <child
      link="b111" />
    <axis
      xyz="-0.70841 0.7058 0" />
    <limit
      lower="-3.14"
      upper="3.14"
      effort="1"
      velocity="1" />
    <dynamics
      damping="1"
      friction="1" />
  </joint>
  <link
    name="b2">
    <inertial>
      <origin
        xyz="0 0 0"
        rpy="0 0 0" />
      <mass
        value="0" />
      <inertia
        ixx="0"
        ixy="0"
        ixz="0"
        iyy="0"
        iyz="0"
        izz="0" />
    </inertial>
    <visual>
      <origin
        xyz="0 0 0"
        rpy="0 0 0" />
      <geometry>
        <mesh
          filename="package://spider/meshes/b2.STL" />
      </geometry>
      <material
        name="">
        <color
          rgba="1 1 1 1" />
      </material>
    </visual>
    <collision>
      <origin
        xyz="0 0 0"
        rpy="0 0 0" />
      <geometry>
        <mesh
          filename="package://spider/meshes/b2.STL" />
      </geometry>
    </collision>
  </link>
  <joint
    name="b2_joint"
    type="revolute">
    <origin
      xyz="0.037828 -0.030487 0.022299"
      rpy="0 0 0" />
    <parent
      link="base_link" />
    <child
      link="b2" />
    <axis
      xyz="0 0 -1" />
    <limit
      lower="-3.14"
      upper="3.14"
      effort="1"
      velocity="1" />
    <dynamics
      damping="1"
      friction="1" />
  </joint>
  <link
    name="b22">
    <inertial>
      <origin
        xyz="0.027923 -0.0027666 0.012991"
        rpy="0 0 0" />
      <mass
        value="0.0073206" />
      <inertia
        ixx="1.9761E-06"
        ixy="-1.0533E-07"
        ixz="-5.4409E-07"
        iyy="1.9406E-06"
        iyz="4.6686E-07"
        izz="2.9301E-06" />
    </inertial>
    <visual>
      <origin
        xyz="0 0 0"
        rpy="0 0 0" />
      <geometry>
        <mesh
          filename="package://spider/meshes/b22.STL" />
      </geometry>
      <material
        name="">
        <color
          rgba="0.79216 0.81961 0.93333 1" />
      </material>
    </visual>
    <collision>
      <origin
        xyz="0 0 0"
        rpy="0 0 0" />
      <geometry>
        <mesh
          filename="package://spider/meshes/b22.STL" />
      </geometry>
    </collision>
  </link>
  <joint
    name="b22_joint"
    type="revolute">
    <origin
      xyz="0.013409 -0.026621 -0.010175"
      rpy="0 0 0" />
    <parent
      link="b2" />
    <child
      link="b22" />
    <axis
      xyz="0.65041 0.75958 0" />
    <limit
      lower="-3.14"
      upper="3.14"
      effort="1"
      velocity="1" />
    <dynamics
      damping="1"
      friction="1" />
  </joint>
  <link
    name="b222">
    <inertial>
      <origin
        xyz="0.016762 0.0063204 -0.0098613"
        rpy="0 0 0" />
      <mass
        value="0.013124" />
      <inertia
        ixx="3.6412E-06"
        ixy="5.2062E-07"
        ixz="1.2888E-06"
        iyy="3.7771E-06"
        iyz="-1.1848E-06"
        izz="2.0184E-06" />
    </inertial>
    <visual>
      <origin
        xyz="0 0 0"
        rpy="0 0 0" />
      <geometry>
        <mesh
          filename="package://spider/meshes/b222.STL" />
      </geometry>
      <material
        name="">
        <color
          rgba="0.79216 0.81961 0.93333 1" />
      </material>
    </visual>
    <collision>
      <origin
        xyz="0 0 0"
        rpy="0 0 0" />
      <geometry>
        <mesh
          filename="package://spider/meshes/b222.STL" />
      </geometry>
    </collision>
  </link>
  <joint
    name="b222_joint"
    type="revolute">
    <origin
      xyz="0.036379 -0.03115 0.027042"
      rpy="0 0 0" />
    <parent
      link="b22" />
    <child
      link="b222" />
    <axis
      xyz="0.65041 0.75958 0" />
    <limit
      lower="-3.14"
      upper="3.14"
      effort="1"
      velocity="1" />
    <dynamics
      damping="1"
      friction="1" />
  </joint>
</robot>
